Workbook

Sheet Summary
A1: Road Pulse – honest test on 50 hand-labelled reports
A2: Labels by one person (column my_label). Model 1 = cardiffnlp/twitter-roberta-base-sentiment-latest. Model 2 = VADER word list (compound ≥ 0.05 positive, ≤ -0.05 negative, else neutral).
B4: RoBERTa (model 1) | C4: VADER (model 2)
A5: Agrees with my label | B5: =COUNTIF('Test table'!K2:K51,"yes") -> 31 | C5: =COUNTIF('Test table'!L2:L51,"yes") -> 27
A6: Out of | B6: =COUNTA('Test table'!E2:E51) -> 50 | C6: =COUNTA('Test table'!E2:E51) -> 50
A7: Agreement | B7: =B5/B6 -> 0.62 | C7: =C5/C6 -> 0.54
A8: Models disagree with each other | B8: =COUNTIF('Test table'!M2:M51,"yes") -> 13
A10: Confusion matrix – RoBERTa
A11: my label ↓ / model → | B11: negative | C11: neutral | D11: positive
A12: negative | B12: =COUNTIFS('Test table'!E2:E51,"negative",'Test table'!G2:G51,"negative") -> 23 | C12: =COUNTIFS('Test table'!E2:E51,"negative",'Test table'!G2:G51,"neutral") -> 1 | D12: =COUNTIFS('Test table'!E2:E51,"negative",'Test table'!G2:G51,"positive") -> 0
A13: neutral | B13: =COUNTIFS('Test table'!E2:E51,"neutral",'Test table'!G2:G51,"negative") -> 18 | C13: =COUNTIFS('Test table'!E2:E51,"neutral",'Test table'!G2:G51,"neutral") -> 8 | D13: =COUNTIFS('Test table'!E2:E51,"neutral",'Test table'!G2:G51,"positive") -> 0
A14: positive | B14: =COUNTIFS('Test table'!E2:E51,"positive",'Test table'!G2:G51,"negative") -> 0 | C14: =COUNTIFS('Test table'!E2:E51,"positive",'Test table'!G2:G51,"neutral") -> 0 | D14: =COUNTIFS('Test table'!E2:E51,"positive",'Test table'!G2:G51,"positive") -> 0
A16: Confusion matrix – VADER
A17: my label ↓ / model → | B17: negative | C17: neutral | D17: positive
A18: negative | B18: =COUNTIFS('Test table'!E2:E51,"negative",'Test table'!I2:I51,"negative") -> 18 | C18: =COUNTIFS('Test table'!E2:E51,"negative",'Test table'!I2:I51,"neutral") -> 4 | D18: =COUNTIFS('Test table'!E2:E51,"negative",'Test table'!I2:I51,"positive") -> 2
A19: neutral | B19: =COUNTIFS('Test table'!E2:E51,"neutral",'Test table'!I2:I51,"negative") -> 14 | C19: =COUNTIFS('Test table'!E2:E51,"neutral",'Test table'!I2:I51,"neutral") -> 9 | D19: =COUNTIFS('Test table'!E2:E51,"neutral",'Test table'!I2:I51,"positive") -> 3
A20: positive | B20: =COUNTIFS('Test table'!E2:E51,"positive",'Test table'!I2:I51,"negative") -> 0 | C20: =COUNTIFS('Test table'!E2:E51,"positive",'Test table'!I2:I51,"neutral") -> 0 | D20: =COUNTIFS('Test table'!E2:E51,"positive",'Test table'!I2:I51,"positive") -> 0
A22: Green cells = agreement. Read rows: e.g. row 'neutral', column 'negative' = reports I found factual that the model called negative.

Sheet Test table
A1: nr | B1: id | C1: category | D1: report | E1: my_label | F1: note | G1: roberta | H1: roberta_score | I1: vader | J1: vader_score | K1: roberta_agrees | L1: vader_agrees | M1: models_disagree
A2: 1 | B2: 10220851 | C2: Pothole on a road - More than 150mm wide and 40mm deep | D2: Pothole outside 86 Poplar Crescent: Patches seem to have failed - will get worse in winter if not fixed | E2: neutral | F2: no emotions included | G2: negative | H2: -0.8913 | I2: negative | J2: -0.8402 | K2: no | L2: no | M2: no
A3: 2 | B3: 10217893 | C3: Road Potholes | D3: At the start of the 1st of 2 rises towards stondon: Large hole | E3: neutral | F3: location is mentioned | G3: neutral | H3: 0.0147 | I3: neutral | J3: 0 | K3: yes | L3: yes | M3: no
A4: 3 | B4: 10219637 | C4: Footways and Pavement damage | D4: Uneven weed infested bus stop pathway: The pathway Drayton rd Abingdon tithe farm side opposite saxton road bus stop is in need of repair/ replacement due to old crumbling weed infested tarmac . This was reported in 2025 and I was informed that resurfacing of this stretch would be completed 2026 but as of yet nothing. This is a very busy bus stop and used by people with disabilities, elderly, parents with children etc . The curb was lowered a few years ago to cross the road but as you can see in photos not easy to manoeuvre along with crumbling/ weed infested tarmac. We are encouraged to use public transport to ease congestion, air pollution etc but difficult if not accessible for all to do , thanks | E4: negative | F4: angry because it was mentioned and they said they will fix it but still nothing happend | G4: negative | H4: -0.6795 | I4: positive | J4: 0.5008 | K4: yes | L4: no | M4: yes
A5: 4 | B5: 10218760 | C5: Pothole | D5: A Pothole problem has been found 156 Bath Road: A Pothole problem has been found by Oxfordshire County Council 400x400x70 | E5: neutral | G5: negative | H5: -0.553 | I5: negative | J5: -0.6597 | K5: no | L5: no | M5: no
A6: 5 | B6: 10219840 | C6: Pothole | D6: Huge pothole that is increasing in size I have reported this before 3 months ago but nothing has happened: Huge pothole increasing in size I have reported it 3 months ago and no action has been taken | E6: negative | F6: multiple reports | G6: negative | H6: -0.8656 | I6: negative | J6: -0.5563 | K6: yes | L6: yes | M6: no
A7: 6 | B7: 10219014 | C7: Tree growth blocking the pavement | D7: Just complete over growth of brambles and trees: The garden behind is a complete mess tenant cant maintain. Bramble have grown through the trees and hang down, the oak tree part just take more and more path every year, all needs stripping out no 6 used to trim back but they have moved, the grass verge adjacent is quite dangerous due to the levelling of it. | E7: negative | G7: negative | H7: -0.9005 | I7: negative | J7: -0.7302 | K7: yes | L7: yes | M7: no
A8: 7 | B8: 10218649 | C8: Pavements/footpaths | D8: Metal netting/mesh missing?: Is metal netting/mesh missing on the sliperywooden bridge missing? | E8: neutral | F8: I cant realy understand | G8: negative | H8: -0.5448 | I8: negative | J8: -0.7149 | K8: no | L8: no | M8: no
A9: 8 | B9: 10217652 | C9: Weeds on roads or footpaths | D9: Chamberlain Gardens: Hello the huge buddleia bush weed growing on the pavement is preventing people from passing without hitting their head on the buddleia. | E9: neutral | G9: negative | H9: -0.7019 | I9: positive | J9: 0.4404 | K9: no | L9: no | M9: yes
A10: 9 | B10: 10219794 | C10: Potholes | D10: Multiple dangerous potholes: Multiple defects to road surface. Previously reported and not actioned | E10: negative | F10: not statisfyed, reported multiple times and still no action has been taken | G10: negative | H10: -0.8557 | I10: negative | J10: -0.7003 | K10: yes | L10: yes | M10: no
A11: 10 | B11: 10217566 | C11: Kerbs - Damaged/Loose | D11: Loose dropped kerbstone: This kerbstone is loose and we have to be careful when entering our driveway as if you drive over one end then the other end raises and could hit our car. My sister also badly stubbed her toe on it and she thinks it’s broken! | E11: negative | F11: because of the "!" | G11: negative | H11: -0.8679 | I11: negative | J11: -0.8588 | K11: yes | L11: yes | M11: no
A12: 11 | B12: 10218111 | C12: Potholes | D12: Sinkhole: Sinkhole that has become worse over the last 2 months Difficult to see from the photos but depth is severe and makes cars travelling over bounce | E12: neutral | F12: no emotions or other things that make it worse | G12: negative | H12: -0.8556 | I12: negative | J12: -0.7351 | K12: no | L12: no | M12: no
A13: 12 | B13: 10218978 | C13: Slabs - Uneven / Damaged / Cracked | D13: Damaged concrete flower bed unsafe.: Damaged walkway on school pathway caused by crashed vehicle onto path and concrete flower bed. | E13: neutral | F13: just a report | G13: negative | H13: -0.8209 | I13: negative | J13: -0.7003 | K13: no | L13: no | M13: no
A14: 13 | B14: 10219315 | C14: Pavement damage | D14: 177 normal road: Tree damaged pavement | E14: neutral | F14: location is mentioned | G14: neutral | H14: -0.4041 | I14: negative | J14: -0.4404 | K14: yes | L14: no | M14: yes
A15: 14 | B15: 10218922 | C15: Manhole cover - sunken, loose or rattling | D15: Sunken iron work at junction: The sunken iron work is in the middle of the T junction of the Swindon road A361, its very obvious. | E15: neutral | F15: location is mentioned | G15: neutral | H15: -0.1516 | I15: neutral | J15: 0 | K15: yes | L15: yes | M15: no
A16: 15 | B16: 10212313 | C16: Pothole on road/cycleway | D16: Sandon rd grantham near st marys school: The road is like driving across a plowed field,.also on Harrowby rd entrence to the cemetary as you drive along to enter the kerb on one side sticks out about further than the other i think it wants a reflective post on it i have seen cars hit it | E16: negative | F16: the writer made a comparison so he/she can show how bad it is | G16: negative | H16: -0.6465 | I16: positive | J16: 0.3612 | K16: yes | L16: no | M16: yes
A17: 16 | B17: 10219505 | C17: Pothole | D17: Potholes in front of 59 Suffield Road: Potholes in front of 59 Suffield Road | E17: neutral | F17: location is mentioned | G17: neutral | H17: -0.4214 | I17: neutral | J17: 0 | K17: yes | L17: yes | M17: no
A18: 17 | B18: 10220826 | C18: Any other pavement issue | D18: Cracked tarmac - trip hazard: Outside 34 / 36 Poplar Crescent | E18: neutral | F18: location is mentioned | G18: negative | H18: -0.5889 | I18: neutral | J18: 0 | K18: no | L18: yes | M18: yes
A19: 18 | B19: 10217409 | C19: Other issue with the road surface | D19: Severn Trent did work and flushed out a drain and since then the road is covered in muck making it VERY slippy and it’s thick.: Outside number 2 jubilee Avenue, Cam GL115JJ | E19: neutral | F19: location is mentioned | G19: negative | H19: -0.7654 | I19: positive | J19: 0.0772 | K19: no | L19: no | M19: yes
A20: 19 | B20: 10218486 | C20: Footpath / pavement problem | D20: Pavement cover caving in and broken: On Micklefield road outside house 130. A few days ago a dustbin lorry was parked on the path for about 30mins. When they moved the concrete groundworks cover had been broken and is caving in! This could be quite dangerous for people walking on the path. And seems to be getting worse. | E20: negative | F20: locatuin is mentioned and "!" is used | G20: negative | H20: -0.7903 | I20: negative | J20: -0.9183 | K20: yes | L20: yes | M20: no
A21: 20 | B21: 10220987 | C21: Pothole on a road - More than 150mm wide and 40mm deep | D21: Pothole / road damage at entrance to Colville Gardens: Pothole, likely to cause car / car tyre damage. Getting worse. | E21: negative | F21: "getting worse" give it a bad impression | G21: negative | H21: -0.8446 | I21: negative | J21: -0.8591 | K21: yes | L21: yes | M21: no
... A24: 23 | B24: 10221049 | C24: Pothole on road/cycleway | D24: Very poor condition: Road is very poor and is like driving on a dirt track | E24: negative | F24: "very poor" | G24: negative | H24: -0.9211 | I24: negative | J24: -0.7708 | K24: yes | L24: yes | M24: no
A25: 24 | B25: 10217902 | C25: Road Potholes | D25: Shortly before jct for nursery: Large hole on inside of road towards roundabout | E25: neutral | G25: neutral | H25: -0.3996 | I25: neutral | J25: 0 | K25: yes | L25: yes | M25: no
A26: 25 | B26: 10217972 | C26: Pothole | D26: Pothole and crack forming in road around manhole.: Pothole has formed on edge of road with the roadway breaking up around it. Water now pools. Also at this section a crack is opening up around the manhole cover. Could this please be assessed for works. Thank you kindly. | E26: neutral | G26: negative | H26: -0.5308 | I26: positive | J26: 0.8087 | K26: no | L26: no | M26: yes
A27: 26 | B27: 10218181 | C27: Pothole | D27: tMC - Defects -FW6 Potholes problem: FWPH STATS REQUIRED 2500 X 700 X 25mm STANDARD TM WITH FOOTWAY CLOSURE MARKED (FW6 Pothole) | E27: neutral | F27: location is mentioned | G27: negative | H27: -0.8334 | I27: negative | J27: -0.6597 | K27: no | L27: no | M27: no
A28: 27 | B28: 10220154 | C28: Pothole on a road - More than 150mm wide and 40mm deep | D28: Pothole under railway bridge: Pothole under railway bridge. This has been repaired before. Road is only wide enough for single file traffic under bridge, so pothole is hard to avoid. | E28: neutral | G28: negative | H28: -0.6791 | I28: negative | J28: -0.4336 | K28: no | L28: no | M28: no
A29: 28 | B29: 10220939 | C29: Pavements/footpaths | D29: Sheets of metal: Two big sheets of metal on psalter lane half on grass and half on pavment Between Ecclesall ro and hunter house rd Just before the brow of the hill | E29: neutral | F29: location is mentioned | G29: neutral | H29: -0.0785 | I29: neutral | J29: 0 | K29: yes | L29: yes | M29: no
A30: 29 | B30: 10218105 | C30: Potholes | D30: Several small potholes on both sides of the road.: Potholes have been spreading for two years. | E30: negative | F30: time mentioned make it worse | G30: negative | H30: -0.7188 | I30: neutral | J30: 0 | K30: yes | L30: no | M30: yes
A31: 30 | B31: 10217935 | C31: Pothole on a road - More than 150mm wide and 40mm deep | D31: Recurring pothole on Princes Road: I think I may have reported a pothole at this exact spot a few years ago, it was quickly filled and repaired but it was not sealed so not surprisingly it has opened up again. Can you please demand that the contractors apply a tar sealant this time to prevent it failing so quickly again? | E31: negative | F31: multiple reports | G31: negative | H31: -0.679 | I31: negative | J31: -0.705 | K31: yes | L31: yes | M31: no
A32: 31 | B32: 10220707 | C32: Pavements/footpaths | D32: Unlit Obstacle on Cycle Path: On the cycle path between Cowfold Road overpass and the Bolney (NB) slip road there are a number of structure for road signs. None of these structures are lit nor do their supports have reflective markings. These obstacles encroach on the paved area of the cycleway or cycle way boundary and as such, CD195 and Active Travel England outline that any obstacle which does encroach on a cycleway must have reflective marking on it or cyclists at night. Please see the attached photo demonstrating this issue. | E32: neutral | F32: location is mentioned | G32: negative | H32: -0.5229 | I32: negative | J32: -0.5283 | K32: no | L32: no | M32: no
A33: 32 | B33: 10218107 | C33: Pothole | D33: At least two potholes: There are at least two potholes on Caldecott road. Both are on the South side of the road, one nearer the kerb and one nearer the middle of the road, making it hard to avoid both when heading west. | E33: neutral | G33: negative | H33: -0.773 | I33: negative | J33: -0.3818 | K33: no | L33: no | M33: no
A34: 33 | B34: 10218536 | C34: Other issue with a footway/pavement | D34: Blocked pavement: Unable to use pavement safely with my pram. Pavement is too overgrown with shrubs and blocked by soil debris only half the width of the pavement forcing me and pram onto road. Someone appears to have started clearing it and given up! Unable to get to Bourton-on-the-Water. | E34: negative | F34: emotions detected | G34: negative | H34: -0.8811 | I34: neutral | J34: 0 | K34: yes | L34: no | M34: yes
A35: 34 | B35: 10217616 | C35: Pothole on a road - More than 150mm wide and 40mm deep | D35: Multiple potholes on Sole Farm Road: There are multiple potholes 2 or 3 of which are quite large and can do some damage to your car. The potholes have been there for about 2 months but have significantly worsened in the last 3 weeks | E35: negative | F35: consequences given | G35: negative | H35: -0.8191 | I35: negative | J35: -0.714 | K35: yes | L35: yes | M35: no
A36: 35 | B36: 10220958 | C36: Pavement Defect (uneven surface / cracked paving slab) | D36: Brick middinh: Outside no 263 zrudhry green On footpath between green going towards bus stop. Brick is missing. Trip hazard | E36: negative | F36: location and qonsequences mentioned | G36: negative | H36: -0.6573 | I36: negative | J36: -0.5267 | K36: yes | L36: yes | M36: no
A37: 36 | B37: 10218076 | C37: Pothole | D37: Pothole: Pothole | E37: neutral | G37: neutral | H37: -0.2363 | I37: neutral | J37: 0 | K37: yes | L37: yes | M37: no
A38: 37 | B38: 10218819 | C38: Trip hazard/uneven surface | D38: Outside 7 southview moor road: The pavement always seems damp and over last year holes have appeared in it. After rain the mud from holes runs over pavement and recently green slime has started to coat this area. It's very slippery and uneven | E38: negative | F38: consequences given | G38: negative | H38: -0.7705 | I38: neutral | J38: 0 | K38: yes | L38: no | M38: yes
A39: 38 | B39: 10218859 | C39: Loose / Raised/Sunken | D39: Loose cover: Manhole cover is loose and every time a car drives over it is making a loud clanking noise | E39: neutral | G39: negative | H39: -0.6925 | I39: negative | J39: -0.5574 | K39: no | L39: no | M39: no
A40: 39 | B40: 10220861 | C40: Pavements/Cycleway | D40: Narrow and big humps: This pavement is narrow already and has huge humps due to tree roots - disabled person struggling to walk it | E40: negative | F40: consequences given | G40: negative | H40: -0.8113 | I40: negative | J40: -0.128 | K40: yes | L40: yes | M40: no
A41: 40 | B41: 10219667 | C41: TMC - Defects -FW6 Potholes | D41: TMC - Defects -FW6 Potholes problem: FWPH STATS REQUIRED 2500 X 700 X 25mm STANDARD TM WITH FOOTWAY CLOSURE MARKED (FW6 Pothole) | E41: neutral | F41: location is mentioned | G41: negative | H41: -0.6003 | I41: negative | J41: -0.6597 | K41: no | L41: no | M41: no
A42: 41 | B42: 10218943 | C42: Pavements/footpaths | D42: Raised curb stone, possibly void and bowing of pavement opposite: Curb stone been loose a few months but now dropped considerably | E42: negative | F42: long period problem | G42: neutral | H42: -0.3711 | I42: negative | J42: -0.1655 | K42: no | L42: yes | M42: yes
...

Sheet Failures
A1: nr | B1: report (shortened) | C1: my label | D1: model said | E1: type | F1: why the model got it wrong
A2: 26 | B2: TMC - Defects -FW6 Potholes problem: FWPH STATS REQUIRED 2500 X 700 X 25mm STANDARD TM WITH FOOTWAY CLOSURE MARKED | C2: neutral | D2: RoBERTa: negative (-0.83) | E2: Jargon / not a human voice | F2: This is an internal council work order, not a citizen. Capitals and words like 'Defects' and 'problem' look angry to a model trained on tweets, but there is no emotion at all. Same text appears twice in the sample (nr 26 and 40): both wrong.
A3: 17 | B3: Cracked tarmac - trip hazard: Outside 34 / 36 Poplar Crescent | C3: neutral | D3: RoBERTa: negative (-0.59) | E3: Negative topic ≠ negative feeling | F3: The model reacts to the words 'cracked' and 'hazard'. On a pothole platform almost every report has negative words, so the model mistakes the subject for the mood. This is the main pattern: 18 of 26 factual reports were called negative.
A4: 25 | B4: Pothole and crack forming in road around manhole… Could this please be assessed for works. Thank you kindly. | C4: neutral | D4: RoBERTa: negative (-0.53) · VADER: positive (+0.81) | E4: Mixed message (polite tone, bad news) | F4: A polite request about damage. RoBERTa only sees the damage, VADER only sees 'please' and 'thank you'. Both models are wrong, in opposite directions.
A5: 3 | B5: Uneven weed infested bus stop pathway… reported in 2025… nothing… difficult if not accessible for all…, thanks | C5: negative | D5: VADER: positive (+0.50) | E5: Word list misses context | F5: A long, frustrated complaint that ends with 'thanks'. VADER counts words like 'thanks', 'encouraged', 'ease' and adds them up; it cannot see that the message as a whole is a complaint. RoBERTa got this one right.
A6: 41 | B6: Raised curb stone, possibly void and bowing of pavement opposite: Curb stone been loose a few months but now dropped considerably | C6: negative | D6: RoBERTa: neutral (-0.37) | E6: Implicit frustration | F6: The frustration is in the facts ('a few months', 'now dropped considerably'), not in emotional words. The model needs explicit feeling words to call something negative.
